Workbook

Sheet Summary
A1: Commissionerate of Technical Education, Gujarat State, Gandhinagar
A2: New Item for the Year 2025-26
A3: Summary
A4: Name of Institute: L.D College of Engineering, Ahmedabad | G4: Type of Course: U.G
A5: Principal Name: | C5: Dr N N BUPTANI | E5: Mobile No:- | F5: 9909920670
J6: Amount in Rs. | K6: =K9 -> 178817913
A7: Course Type (Diploma/UG/PG) | B7: Non-IT Equipments | D7: Total amount for Non-IT Equipments | E7: Total amount for IT Equipments | F7: Furniture | H7: Total amount for Furniture | I7: Total amount for Books | J7: Total amount for Maintainance | K7: Grand Total
B8: Less than Rs.5.00 Lakh | C8: More than Rs.5.00 Lakh | F8: Less than Rs.5.00 Lakh | G8: More than Rs.5.00 Lakh
A9: U.G | B9: 12543000 | C9: 55479500 | D9: =B9+C9 -> 68022500 | E9: ='Statement 2 (IT Equipment)-U.G'!F24 -> 73110000 | F9: ='Statement 3 (Furniture)-U.G'!E24 -> 2385500 | G9: ='Statement 3 (Furniture)-U.G'!E45 -> 30394500 | H9: =F9+G9 -> 32780000 | I9: 2179813 | J9: ='Statement 5 Maintanance-UG'!E61 -> 2725600 | K9: =D9+E9+H9+I9+J9 -> 178817913
H13: Institute Seal | J13: Principal Sign
A14: નોંધ:-Diploma, UG અને PG અભ્યાસક્રમ માટે અલગ અલગ પત્રકો તૈયાર કરી માહિતી આપવી.

Sheet Equip-NI-2025-26
A1: LDCE-Vikashlakshi Equipment demand-2025-26 (Except IT equipment & Furniture)
A2: Dept. | B2: U.G | C2: P.G | D2: Total Demand | E2: Commited Budget to be spent | G2: Process | H2: Order Placed | I2: Under DLPC-Eqp. | J2: Under DPC-Eqp. | K2: Not Approved | L2: Bill Amount
A3: Applied Mechanics | B3: 2097000 | C3: 0 | D3: =B3+C3 -> 2097000 | E3: =600000+-600000+2000000 -> 2000000 | G3: =87000+80000 -> 167000 | H3: 18079 | L3: =9899+3000+1980 -> 14879
A4: Automobile | B4: 884500 | C4: 0 | D4: =B4+C4 -> 884500 | E4: 400000 | G4: =515000+150000 -> 665000 | H4: 0
A5: Biomedical | B5: 1220000 | C5: 0 | D5: =B5+C5 -> 1220000 | E5: =1200000+1000000 -> 2200000 | G5: 3000000 | H5: =48300+58587+58410 -> 165297 | L5: =58587+58410 -> 116997
A6: Chemical | B6: 1409000 | C6: 4700000 | D6: =B6+C6 -> 6109000 | E6: =6100000+400000 -> 6500000 | G6: 9159000 | H6: 21776 | I6: 3020190 | L6: 21200
A7: Civil | B7: 2399000 | C7: 0 | D7: =B7+C7 -> 2399000 | E7: 1135000 | G7: =535000+600000 -> 1135000 | H7: 0 | J7: 1687484
A8: Computer Eng | B8: 1295000 | C8: 0 | D8: =B8+C8 -> 1295000 | E8: 0 | G8: 0 | H8: 0
A9: Electrical | B9: =2635000+4180000 -> 6815000 | C9: 0 | D9: =B9+C9 -> 6815000 | E9: =2600000+2600000 -> 5200000 | G9: =521000+20000+20000+15000+22000 -> 598000 | H9: =24800+7000+16000+15000 -> 62800 | I9: 81000 | L9: =24800+15000+7000+16000 -> 62800
A10: EC | B10: 0 | C10: 0 | D10: 0 | E10: 3500000 | G10: 3500000 | H10: 0 | J10: 5242500
A11: Environment | B11: 2081000 | C11: 675000 | D11: =B11+C11 -> 2756000 | E11: =2000000+1500000 -> 3500000 | G11: =2581000+350000 -> 2931000 | H11: =5754+22001 -> 27755 | L11: =5754+21891 -> 27645
A12: IC | B12: 0 | C12: 0 | D12: =B12+C12 -> 0 | E12: 9000000 | G12: 5034950 | H12: 0 | I12: 269000
A13: IT | B13: 150000 | C13: 0 | D13: =B13+C13 -> 150000 | E13: 0 | G13: 0 | H13: 0
A14: Library | B14: 520000 | C14: 0 | D14: =B14+C14 -> 520000 | E14: 0 | G14: 520000 | H14: 0
A15: Mechanical | B15: 8130000 | C15: 1050000 | D15: =B15+C15 -> 9180000 | E15: =5000000-3200000 -> 1800000 | G15: 2080000 | H15: 0 | I15: 64400
A16: Plastic Tech | B16: 225000 | C16: 0 | D16: =B16+C16 -> 225000 | E16: 7500000 | G16: 0 | H16: 0
A17: Rubber | B17: 1110000 | C17: 0 | D17: =B17+C17 -> 1110000 | E17: 600000 | G17: 560000 | H17: 0 | I17: 189000 | K17: 39900
A18: S & H | B18: 0 | C18: 0 | D18: 0 | E18: 0 | G18: =23225+2289500+310000+90000 -> 2712725 | H18: =22224+1000 -> 23224 | L18: 990
A19: Textile | B19: 15222000 | C19: 415000 | D19: =B19+C19 -> 15637000 | E19: 15637000 | G19: =1436700+111000+25000 -> 1572700 | H19: =99200+864480+94636+15000 -> 1073316 | J19: =B28+B29 -> 2425009 | L19: =9850+24875+15000 -> 49725
A20: Common Purchase (Central Store) | B20: 24985000 | C20: 3870000 | D20: =B20+C20 -> 28855000 | E20: 3350000 | G20: 3350000 | H20: 0 | J20: 3075300
A21: Institute Services | I21: 235950 | J21: 6479737
A22: Grand Total | B22: =SUM(B3:B20) -> 68542500 | C22: =SUM(C3:C20) -> 10710000 | D22: =B22+C22 -> 79252500 | E22: =SUM(E3:E20) -> 62322000 | G22: =SUM(G3:G20) -> 36985375 | H22: =SUM(H3:H20) -> 1392247 | I22: =SUM(I3:I21) -> 3859540 | J22: =SUM(J3:J21) -> 18910030 | K22: =SUM(K3:K20) -> 39900 | L22: =SUM(L3:L20) -> 294236
A25: Unde DPC | G25: Order released for services
A26: Name of Equipment | B26: L1 Amount | C26: Party | D26: Dept. | G26: Name of Service | H26: L1 Amount
A27: Air Conditioners-67 Nos. | B27: 3075300 | C27: Vedanta Equipment Pvt. Ltd. | D27: Central Store | G27: 1. Fire Safety for Hostel | H27: 2345000
A28: Miniature Rotor Spinning M/c | B28: 1189220 | C28: T4 Textultants Pvt. Ltd. | D28: Textile | G28: 2 AMC-Hostel- RO | H28: 164880 | J28: 123960 | K28: =J28*3/100 -> 3718.8
A29: Miniature Ring frame | B29: 1235789 | C29: T4 Textultants Pvt. Ltd. | D29: Testile | G29: 3. AMC-Institute-HK | H29: 9908765 | J29: 130164 | K29: =J29*3/100 -> 3904.92
A30: Sound Level Meter | B30: 1687484 | C30: Technovision Analytical | D30: IC, Civil. Chemical, Environment | G30: 4 AMC-Hostel HK | H30: 4565977
A31: Manpower Outsourcing | B31: 6479737 | C31: Hindusthan Services | D31: Institute Services | H31: =SUM(H27:H30) -> 16984622
A32: Electronics Workbench | B32: 5242500 | C32: Premier Enterprise | D32: EC,IC,Biomedical
B33: =SUM(B27:B32) -> 18910030

Sheet Sheet3
A1: Status | B1: Bill submitted
A2: Product /Service | B2: Equipment
A4: Row Labels | B4: Sum of Total Amount (Rs.) | C4: Sum of Bill Net Amount
A5: Applied Mechanics | B5: 1528000 | C5: 1095679
A6: Automobile | B6: 600000 | C6: 333210
A7: Biomedical | B7: 1250000 | C7: 1100572
A8: Central Store-Equipment | B8: 3478000 | C8: 3155052
A9: Chemical | B9: 10717000 | C9: 5724628
A10: Civil | B10: 535000 | C10: 421500
A11: Electrical | B11: 3519000 | C11: 1740553
A12: Environment | B12: 2401000 | C12: 1584480
A13: I.C | B13: 3145690 | C13: 2469000
A14: Mechanical | B14: 762916 | C14: 556454
A15: Plastic Tech | B15: 360000 | C15: 239900
A16: Rubber Tech | B16: 1695000 | C16: 1077531
... A19: Grand Total | B19: 36764306 | C19: 25575782

Sheet Statement 1 (Non-IT Equip)
A1: L.D College of Engineering, Ahmedabad | N1: =E4-M4 -> 11072787 | O1: Price diff | Q1: =M4-P4 -> 115737 | R1: Panalty
A2: Procurement Status- F.Y-2025-26
A3: Sr. | B3: Name of Item | C3: Qty. Required | D3: Approx. Rate (Rs.) | E3: Total Amount (Rs.) | F3: Department / Discipline | G3: Avalable Qty. | H3: Detailed Justification | I3: Available on GeM? (Yes or No) | J3: U.G/P.G | K3: Product /Service | L3: Status | M3: L1 Amount | N3: Party | O3: Remarks | P3: Bill Net Amount | Q3: Bill No. | R3: Date | S3: S.D | T3: Rs. | U3: Remarks
A4: =SUBTOTAL(2,A5:A338)+22+14+9 -> 141 | B4: All Filter | C4: =SUBTOTAL(9,C5:C338) -> 373 | D4: Total | E4: =SUBTOTAL(9,E5:E338) -> 36764306 | F4: All Filter | G4: =SUBTOTAL(9,G5:G322) -> 28 | H4: All Filter | I4: All Filter | J4: All Filter | K4: All Filter | L4: All Filter | M4: =SUBTOTAL(9,M5:M338) -> 25691519 | N4: All Filter | O4: All Filter | P4: =SUBTOTAL(9,P5:P338) -> 25575782 | Q4: All Filter | R4: All Filter | S4: All Filter
A5: 1 | B5: Slump test apparatus with tamping rod | C5: 1 | D5: 3000 | E5: =C5*D5 -> 3000 | F5: Applied Mechanics | G5: 1 | H5: Basic requiremnet at UG and PG level research and testing | I5: yes | J5: U.G | K5: Equipment | L5: Bill submitted | M5: 2000 | N5: Steel Fabricators | O5: DP | P5: 1980 | Q5: GEM-63696205 | R5: 45913 | S5: N.A
A6: =A5+1 -> 2 | B6: Nonconcurrent coplanar force apparatus | C6: 1 | D6: 9000 | E6: =C6*D6 -> 9000 | F6: Applied Mechanics | G6: 1 | H6: Basic requiremnet at UG level | I6: yes | J6: U.G | K6: Equipment | L6: Rejected | M6: 2080 | O6: DP | P6: 0 | Q6: N.A | R6: N.A | S6: N.A
A7: =A6+1 -> 3 | B7: Weighing scale 5 kg with 1 gm resolution | C7: 1 | D7: 12000 | E7: =C7*D7 -> 12000 | F7: Applied Mechanics | G7: 1 | H7: Basic requiremnet at UG and PG level research and testing | I7: yes | J7: U.G | K7: Equipment | L7: Bill submitted | M7: 9999 | N7: B.R Chemical Suppliers, Jodhpur | O7: DP | P7: 9899 | Q7: GEM-62062887 | R7: 45875 | S7: N.A
A8: =A7+1 -> 4 | B8: Weighing scale 10 kg with 10 gm resolution | C8: 1 | D8: 13000 | E8: =C8*D8 -> 13000 | F8: Applied Mechanics | G8: 1 | H8: Basic requiremnet at UG and PG level research and testing | I8: yes | J8: U.G | K8: Equipment | L8: Bill submitted | M8: 3000 | N8: Apolo scale industry, Agra | O8: DP | P8: 3000 | Q8: GEM-63342027 | R8: 45905 | S8: N.A
A9: =A8+1 -> 5 | B9: Two Hinged Arch Apparatus | C9: 1 | D9: 80000 | E9: =C9*D9 -> 80000 | F9: Applied Mechanics | G9: 0 | H9: Basic requiremnet at UG level | I9: yes | J9: U.G | K9: Equipment | L9: Rejected | M9: 83500 | N9: Engineering Models & Equipment,Roorkee | O9: DLPC-6 | P9: 0 | Q9: N.A | R9: N.A | S9: Pending
A10: =A9+1 -> 6 | B10: Three Hinged Arch Apparatus | C10: 1 | D10: 80000 | E10: =C10*D10 -> 80000 | F10: Applied Mechanics | G10: 0 | H10: Basic requiremnet at UG level | I10: yes | J10: U.G | K10: Equipment | L10: Rejected | M10: 84200 | N10: Engineering Models & Equipment,Roorkee | O10: DLPC-6 | P10: 0 | Q10: N.A | R10: N.A | S10: Pending
A11: =A10+1 -> 7 | B11: Concrete permeability apparatus | C11: 1 | D11: 90000 | E11: =C11*D11 -> 90000 | F11: Applied Mechanics | G11: 1 | H11: Basic requiremnet at UG and PG level research and testing | I11: yes | J11: U.G | K11: Equipment | L11: Action pending
A12: =A11+1 -> 8 | B12: Portable concrete core cutter | C12: 1 | D12: 360000 | E12: =C12*D12 -> 360000 | F12: Applied Mechanics | G12: 0 | H12: Basic requiremnet at UG and PG level research and testing | I12: yes | J12: U.G | K12: Equipment | L12: Rejected | M12: 202000 | N12: Intellitest Solutions Pvt. Ltd., Faridabad | O12: DLPC-5 | P12: 0 | Q12: N.A | R12: N.A | S12: 502203 | T12: 10100 | U12: ICICI bank
A13: =A12+1 -> 9 | B13: Viscometer | C13: 1 | D13: 24500 | E13: =C13*D13 -> 24500 | F13: Automobile | G13: 0 | H13: UG course | I13: YES | J13: U.G | K13: Equipment | L13: Action pending
A14: =A13+1 -> 10 | B14: Spark plug tester and cleaner | C14: 1 | D14: 45000 | E14: =C14*D14 -> 45000 | F14: Automobile | G14: 0 | H14: UG course | I14: YES | J14: U.G | K14: Equipment | L14: Action pending
A15: =A14+1 -> 11 | B15: Rotary and inline fuel pump | C15: 1 | D15: 50000 | E15: =C15*D15 -> 50000 | F15: Automobile | G15: 0 | H15: UG course | I15: YES | J15: U.G | K15: Equipment | L15: Action pending
A16: =A15+1 -> 12 | B16: Air compressor 5HP | C16: 1 | D16: 65000 | E16: =C16*D16 -> 65000 | F16: Automobile | G16: 0 | H16: UG course | I16: YES | J16: U.G | K16: Equipment | L16: Bid Published
A17: =A16+1 -> 13 | B17: Raspberry pi kit with 8 GB storage | C17: 5 | D17: 20000 | E17: =C17*D17 -> 100000 | F17: Automobile | G17: 0 | H17: UG course | I17: YES | J17: U.G | K17: Equipment | L17: Bid Published
A18: =A17+1 -> 14 | B18: Electronic weighing scale (min. 1000kg) | C18: 1 | D18: 150000 | E18: =C18*D18 -> 150000 | F18: Automobile | G18: 0 | H18: UG course | I18: YES | J18: U.G | K18: Equipment | L18: Bill submitted | M18: 16000 | N18: Maruti Weightech Pvt. Ltd. | O18: DP | P18: 15920 | Q18: GEM-67230898 | R18: 45999 | S18: N.A
A19: =A18+1 -> 15 | B19: SCISSOR LIFT | C19: 1 | D19: 200000 | E19: =C19*D19 -> 200000 | F19: Automobile | G19: 0 | H19: UG course | I19: YES | J19: U.G | K19: Equipment | L19: Bill submitted | M19: 131000 | N19: Pantron Automation Pvt. Ltd. | O19: DLPC-5 | P19: 129690 | Q19: GEM-70289864 | R19: 46066 | S19: Exempted
A20: =A19+1 -> 16 | B20: Gas analyzer ( 5 gas) | C20: 1 | D20: 250000 | E20: =C20*D20 -> 250000 | F20: Automobile | G20: 0 | H20: UG course | I20: YES | J20: U.G | K20: Equipment | L20: Bill submitted | M20: 187600 | N20: Pantron Automation Pvt. Ltd. | O20: DLPC-5 | P20: 187600 | Q20: GEM-71614380 | R20: 46087 | S20: Exempted
A21: =A20+1 -> 17 | B21: Biomedical Sensor Interface Trainer Kit | C21: 3 | D21: 20000 | E21: =C21*D21 -> 60000 | F21: Biomedical | G21: 0 | H21: Required as per GTU syllabus | I21: Yes | J21: U.G | K21: Equipment | L21: Bill submitted | M21: 48300 | N21: Royale Electronics Sales & Services | O21: DLPC-1 | P21: 47576 | Q21: GEM-64369436 | R21: 45927 | S21: 0554825IPG000054
A22: =A21+1 -> 18 | B22: ESP32 IoT Development Trainer Kit | C22: 3 | D22: 20000 | E22: =C22*D22 -> 60000 | F22: Biomedical | G22: 0 | H22: Required as per GTU syllabus | I22: Yes | J22: U.G | K22: Equipment | L22: Bill submitted | M22: 58587 | N22: Prajakta Enterprise | O22: DLPC-1 | P22: 58587 | Q22: GEM-64167332 | R22: 45929 | S22: 004418
A23: =A22+1 -> 19 | B23: PIC Development Board Trainer Kit | C23: 3 | D23: 20000 | E23: =C23*D23 -> 60000 | F23: Biomedical | G23: 0 | H23: Required as per GTU syllabus | I23: Yes | J23: U.G | K23: Equipment | L23: Bill submitted | M23: 58410 | N23: Prajakta Enterprise | O23: DLPC-1 | P23: 58410 | Q23: GEM-64167341 | R23: 45924 | S23: 004419
A24: =A23+1 -> 20 | B24: Orange Pi 5 Plus 32GB Development Kit | C24: 3 | D24: 80000 | E24: =C24*D24 -> 240000 | F24: Biomedical | G24: 0 | H24: Required as per GTU syllabus | I24: Yes | J24: U.G | K24: Equipment | L24: Action pending
A25: =A24+1 -> 21 | B25: NVIDIA Jetson Orin Nano 8GB Developer Kit | C25: 4 | D25: 80000 | E25: =C25*D25 -> 320000 | F25: Biomedical | G25: 0 | H25: For Project Work | I25: Yes | J25: U.G | K25: Equipment | L25: Action pending
A26: =A25+1 -> 22 | B26: Jetson AGX Orin Developer Kit | C26: 2 | D26: 240000 | E26: =C26*D26 -> 480000 | F26: Biomedical | G26: 0 | H26: Required as per GTU syllabus | I26: Yes | J26: U.G | K26: Equipment | L26: Action pending
A27: =A26+1 -> 23 | B27: Heating Mental 500ml | C27: 4 | D27: 1000 | E27: =C27*D27 -> 4000 | F27: Chemical | G27: 0 | H27: UG course (Regular Lab) | I27: Yes | J27: U.G | K27: Equipment | L27: Action pending
A28: =A27+1 -> 24 | B28: Heating Mental 2 lit | C28: 2 | D28: 2000 | E28: =C28*D28 -> 4000 | F28: Chemical | G28: 0 | H28: UG course (Regular Lab) | I28: Yes | J28: U.G | K28: Equipment | L28: Action pending
A29: =A28+1 -> 25 | B29: Heating Mental 1lit | C29: 4 | D29: 1500 | E29: =C29*D29 -> 6000 | F29: Chemical | G29: 0 | H29: UG course (Regular Lab) | I29: Yes | J29: U.G | K29: Equipment | L29: Action pending
A30: =A29+1 -> 26 | B30: Bimettalic Thermometer | C30: 1 | D30: 15000 | E30: =C30*D30 -> 15000 | F30: Chemical | G30: 0 | H30: UG course (Regular Lab) | I30: Yes | J30: U.G | K30: Equipment | L30: Action pending
A31: =A30+1 -> 27 | B31: Magnetic stirrer with heating | C31: 2 | D31: 12000 | E31: =C31*D31 -> 24000 | F31: Chemical | G31: 0 | H31: UG course (Regular Lab) | I31: Yes | J31: U.G | K31: Equipment | L31: Bill submitted | M31: 21776 | N31: M/s Scinos Research & Synthesis, Ahmedabad | O31: DP | P31: 21200 | Q31: GEM-62387604 | R31: 45882 | S31: N.A
A32: =A31+1 -> 28 | B32: Vacuum filtration apparatus with pump | C32: 1 | D32: 25000 | E32: =C32*D32 -> 25000 | F32: Chemical | G32: 0 | H32: UG course (Regular Lab) | I32: Yes | J32: U.G | K32: Equipment | L32: Bill submitted | M32: 21900 | N32: Scinos Research & Synthesis, Ahmedabad | O32: DP | P32: 21890 | Q32: GEM-70993018 | R32: 46077 | S32: NA
A33: =A32+1 -> 29 | B33: Muffle furnace | C33: 1 | D33: 30000 | E33: =C33*D33 -> 30000 | F33: Chemical | G33: 0 | H33: UG course (Regular Lab) | I33: Yes | J33: U.G | K33: Equipment | L33: Action pending
A34: =A33+1 -> 30 | B34: High temperature oil bath (1000 ml capacity) | C34: 1 | D34: 35000 | E34: =C34*D34 -> 35000 | F34: Chemical | G34: 0 | H34: UG course (Regular Lab) | I34: Yes | J34: U.G | K34: Equipment | L34: Bill submitted | M34: 24900 | N34: Scinos Research & Synthesis,Ahmedabad | O34: DP | P34: 24601 | Q34: GEM-71499657 | R34: 46084 | S34: N.A
A35: =A34+1 -> 31 | B35: TDS meter | C35: 3 | D35: 15000 | E35: =C35*D35 -> 45000 | F35: Chemical | G35: 0 | H35: UG course (Regular Lab) | I35: Yes | J35: U.G | K35: Equipment | L35: Action pending
A36: =A35+1 -> 32 | B36: Digital pH meter | C36: 3 | D36: 16000 | E36: =C36*D36 -> 48000 | F36: Chemical | G36: 0 | H36: UG course (Regular Lab) | I36: Yes | J36: U.G | K36: Equipment | L36: Bill submitted | M36: 24314 | N36: Tej Corporation, Punjab | O36: DP | P36: 24192 | Q36: GEM-71480391 | R36: 46084 | S36: N.A
A37: =A36+1 -> 33 | B37: Conductivity meter | C37: 3 | D37: 16000 | E37: =C37*D37 -> 48000 | F37: Chemical | G37: 0 | H37: UG course (Regular Lab) | I37: Yes | J37: U.G | K37: Equipment | L37: Action pending
A38: =A37+1 -> 34 | B38: High temperature oil bath (500 ml capacity) | C38: 2 | D38: 30000 | E38: =C38*D38 -> 60000 | F38: Chemical | G38: 0 | H38: UG course (Regular Lab) | I38: Yes | J38: U.G | K38: Equipment | L38: Bill submitted | M38: 24850 | N38: Scinos Research & Synthesis,Ahmedabad | O38: DP | P38: 24651 | Q38: GEM-71233182 | R38: 46080 | S38: N.A
A39: =A38+1 -> 35 | B39: Syringe Infusion Pump | C39: 3 | D39: 45000 | E39: =C39*D39 -> 135000 | F39: Chemical | G39: 0 | H39: UG course (Regular Lab) | I39: Yes | J39: U.G | K39: Equipment | L39: Action pending
A40: =A39+1 -> 36 | B40: Refractometer | C40: 1 | D40: 450000 | E40: =C40*D40 -> 450000 | F40: Chemical | G40: 0 | H40: UG course (Analytical Lab) | I40: Yes | J40: U.G | K40: Equipment | L40: Action pending
...

Sheet Sheet1
A1: F.Y-2025-26: LDCE-Status of Procurement | D1: All Amount in Rs.
D3: Values
A4: Product /Service | B4: Status | C4: Department / Discipline | D4: Estimated Cost | E4: Sum of L1 Amount
A5: Equipment | B5: Bid Published | C5: Automobile | D5: 165000
C6: Chemical | D6: 2500000
C7: Civil | D7: 2500000
C8: Electrical | D8: 230000
C9: Mechanical | D9: 2490000
C10: Plastic Tech | D10: 8000000
C11: Rubber Tech | D11: 4263000
C12: Central Store-Equipment | D12: 1000000
C13: S&H | D13: 17500
C14: I.C | D14: 4565671
B15: Bid Published Total | D15: 25731171 | F15: Evolution in process
B16: Under DPC | C16: Chemical | D16: 3900000 | E16: 3350000
C17: Civil | D17: 600000 | E17: 596250
C18: Electrical | D18: 2350000 | E18: 2216000
C19: Mechanical | D19: 2000000 | E19: 1896000
C20: Rubber Tech | D20: 1770000 | E20: 1900000
B21: Under DPC Total | D21: 10620000 | E21: 9958250
B22: Bid cancelled | C22: Electrical | D22: 120000 | E22: 0
C23: Electrical | D23: 281000 | E23: 0
C24: Environment | D24: 1780000 | E24: 0
B25: Bid cancelled Total | D25: 2181000 | E25: 0
B26: Order placed | C26: Applied Mechanics | D26: 529000 | E26: 371780
C27: Biomedical | D27: 1750000 | E27: 1048500
C28: Chemical | D28: 700000 | E28: 498900
C29: Electrical | D29: 1205000 | E29: 970100
C30: Rubber Tech | D30: 300000 | E30: 289900
C31: S&H | D31: 247225 | E31: 212224
C32: EC | D32: 3500000 | E32: 2097000
C33: I.C | D33: 4980500 | E33: 3222560
B34: Order placed Total | D34: 13211725 | E34: 8710964
B35: Not approved | C35: Rubber Tech | E35: 0
C36: I.C | D36: 1119950 | E36: 0
B37: Not approved Total | D37: 1119950 | E37: 0
B38: Bill submitted | C38: Applied Mechanics | D38: 1528000 | E38: 1096919
C39: Automobile | D39: 600000 | E39: 334600
C40: Biomedical | D40: 1250000 | E40: 1123247
C41: Chemical | D41: 10717000 | E41: 5757726
...

Sheet DLPC Result
A1: Sr.No. | B1: Sr. | C1: Name of Item | D1: Qty. Required | E1: Approx. Rate (Rs.) | F1: Total Amount (Rs.) | G1: Department / Discipline | H1: U.G/P.G | I1: Product /Service | J1: Status | K1: L1 Amount | L1: Party | M1: Remarks
A2: =SUBTOTAL(2,A3:A97) -> 82 | B2: =SUBTOTAL(2,B3:B97)+1 -> 66 | C2: All Filter | D2: =SUBTOTAL(2,D3:D97) -> 82 | E2: Total | F2: =SUBTOTAL(9,F3:F97) -> 24767000 | G2: All Filter | H2: All Filter | I2: All Filter | J2: All Filter | K2: =SUBTOTAL(9,K3:K91) -> 15612392 | L2: All Filter | M2: All Filter | O2: =F2-K2 -> 9154608
A3: 1 | B3: 17 | C3: Biomedical Sensor Interface Trainer Kit | D3: 3 | E3: 20000 | F3: 60000 | G3: Biomedical | H3: U.G | I3: Equipment | J3: Approved | K3: 48300 | L3: Royale Electronics Sales & Services | M3: DLPC-1
A4: 2 | B4: 18 | C4: ESP32 IoT Development Trainer Kit | D4: 3 | E4: 20000 | F4: 60000 | G4: Biomedical | H4: U.G | I4: Equipment | J4: Approved | K4: 58587 | L4: Prajakta Enterprise | M4: DLPC-1
A5: 3 | B5: 19 | C5: PIC Development Board Trainer Kit | D5: 3 | E5: 20000 | F5: 60000 | G5: Biomedical | H5: U.G | I5: Equipment | J5: Approved | K5: 58410 | L5: Prajakta Enterprise | M5: DLPC-1
A6: 4 | B6: 92 | C6: Reynolds Apparatus | D6: 1 | E6: 60000 | F6: 60000 | G6: Rubber Tech | H6: U.G | I6: Equipment | J6: Not approved | K6: 39900 | L6: Roorkee Equipments | M6: Not Approved, L1 Vendor EMD exception not valid-DLPC-1
A7: 5 | B7: 125 | C7: Automatic Tensile Strength Tester 500 kg +1000kg(Strio & Grab + Lea + Tear + Tenacity + Seam Slippage + Peal bond Strength + Stretch Recovery) | D7: 1 | E7: 1138000 | F7: 1138000 | G7: Textile | H7: U.G | I7: Equipment | J7: Approved | K7: 864480 | L7: Mag Solvics Pvt. Ltd. | M7: DLPC-1
A8: 6 | B8: 6 | C8: AMC for RO plant for Hostel | D8: 1 | E8: 300000 | F8: 300000 | G8: Hostel-Services | H8: Add on | I8: Service | J8: Approved | K8: 164880 | L8: Pure oxidant Tech. Pvt.Ltd. | M8: DLPC-1
A9: 7 | B9: 31 | C9: ICI Pilling Tester - 2 Boxes | D9: 1 | E9: 111000 | F9: 111000 | G9: Textile | H9: Add on | I9: Equipment | J9: Approved | K9: 94636 | L9: Mag Solvics Pvt. Ltd. | M9: DLPC-1
A10: 1 | B10: 1 | C10: Kinetics of Dissolution of Benzoic Acid | D10: 1 | E10: 140000 | F10: 140000 | G10: Chemical | H10: Add on | I10: Equipment | J10: Approved | K10: 78842 | L10: Technology Exchange Services Pvt. Ltd. | M10: DLPC-2
A11: 2 | B11: 2 | C11: Cascade Continuously Stirred Tank Reactor (Compressed Air Feed System) | D11: 1 | E11: 250000 | F11: 250000 | G11: Chemical | H11: Add on | I11: Equipment | J11: Approved | K11: 146706 | L11: Technology Exchange Services Pvt. Ltd. | M11: DLPC-2
A12: 3 | B12: 3 | C12: Fluidized bed reactor | D12: 1 | E12: 300000 | F12: 300000 | G12: Chemical | H12: Add on | I12: Equipment | J12: Approved | K12: 119760 | L12: Technology Exchange Services Pvt. Ltd. | M12: DLPC-2
A13: 4 | B13: 4 | C13: Combined Flow Reactor (Peristaltic Pump Feed System) | D13: 1 | E13: 310000 | F13: 310000 | G13: Chemical | H13: Add on | I13: Equipment | J13: Approved | K13: 117754 | L13: Technology Exchange Services Pvt. Ltd. | M13: DLPC-2
A14: 5 | B14: 5 | C14: Control Valve Characteristic | D14: 1 | E14: 320000 | F14: 320000 | G14: Chemical | H14: Add on | I14: Equipment | J14: Approved | K14: 187600 | L14: Technology Exchange Services Pvt. Ltd. | M14: DLPC-2
... A22: 13 | B22: 1 | C22: Multi Output DC Power Supply | D22: 20 | E22: 25000 | F22: 500000 | G22: I.C. | H22: Add on | I22: Equipment | J22: Approved | K22: 269000 | L22: Batra trading Co., Haryana | M22: DLPC-2
A23: 14 | B23: 95R | C23: UV visible Spectrophotometer | D23: 1 | E23: 500000 | F23: 500000 | G23: Rubber Tech | H23: Add on | I23: Equipment | J23: Approved | K23: 189000 | L23: Gurukripa Enterprises, Bharuch | M23: DLPC-2
A24: 15 | B24: 1 | C24: Tube lights | D24: 1000 | E24: 170 | F24: 170000 | G24: Electrical | H24: Add on | I24: Consumable | J24: Approved | K24: 81000 | L24: A B Pal Electronics Pvt. Ltd., Delhi | M24: DLPC-2
A25: 1 | B25: 64 | C25: Water Bath | D25: 1 | E25: 40000 | F25: 40000 | G25: Environment | H25: U.G | I25: Equipment | J25: Approved | K25: 29890 | L25: Gurukripa Enterprises, Ahmedabad | M25: DLPC-3
A26: 2 | B26: 65 | C26: Laboratory stirrer | D26: 2 | E26: 20000 | F26: 40000 | G26: Environment | H26: U.G | I26: Equipment | J26: Approved | K26: 38740 | L26: Gurukripa Enterprises, Ahmedabad | M26: DLPC-3
A27: 3 | B27: 67 | C27: Magnetic Stirrer | D27: 6 | E27: 25000 | F27: 150000 | G27: Environment | H27: U.G & P.G | I27: Equipment | J27: Approved | K27: 149280 | L27: Gurukripa Enterprises, Ahmedabad | M27: DLPC-3
A28: 4 | B28: 68 | C28: Turbidity meter | D28: 2 | E28: 40000 | F28: 80000 | G28: Environment | H28: U.G | I28: Equipment | J28: Approved | K28: 53000 | L28: Gurukripa Enterprises, Ahmedabad | M28: DLPC-3
A29: 5 | B29: 69 | C29: Laboratory Incubator | D29: 1 | E29: 81000 | F29: 81000 | G29: Environment | H29: U.G | I29: Equipment | J29: Approved | K29: 58700 | L29: M/S Hightech Instruments, Chandigarh | M29: DLPC-3
A30: 6 | B30: 70 | C30: Flame photometer | D30: 1 | E30: 90000 | F30: 90000 | G30: Environment | H30: U.G | I30: Equipment | J30: Approved | K30: 41900 | L30: Batra Trading Co., Ambala | M30: DLPC-3
A31: 7 | B31: 72 | C31: Laminar Air flow | D31: 1 | E31: 200000 | F31: 200000 | G31: Environment | H31: U.G | I31: Equipment | J31: Approved | K31: 98800 | L31: Creative Lab world, Delhi | M31: DLPC-3
A32: 8 | B32: 73 | C32: Laboratory Refrigerator | D32: 1 | E32: 200000 | F32: 200000 | G32: Environment | H32: U.G | I32: Equipment | J32: Approved | K32: 165275 | L32: Advance Biotech Solutions Pvt. Ltd, Delhi | M32: DLPC-3
A33: 9 | B33: 12 | C33: Fume Hood | D33: 1 | E33: 350000 | F33: 350000 | G33: Environment | H33: P.G | I33: Equipment | J33: Approved | K33: 305000 | L33: Narang Scientific Works Pvt. Ltd., New Delhi | M33: DLPC-3
A34: 10 | B34: 0 | C34: Miniature handloom machine | D34: 1 | E34: 200000 | F34: 200000 | G34: Textile | H34: Add on | I34: Equipment | J34: Approved | K34: 198500 | L34: Hindustan weaving looms, Azamgarh | M34: DLPC-3
A35: 11 | B35: 30 | C35: Abrasion cum Pilling Tester - Martindale Type | D35: 1 | E35: 302000 | F35: 302000 | G35: Textile | H35: Add on | I35: Equipment | J35: Approved | K35: 257240 | L35: Mag Solvics Pvt. Ltd. | M35: DLPC-3
A36: 12 | B36: 7 | C36: Dignostic Instrumentation Educational Kits | D36: 2 | E36: 230000 | F36: 460000 | G36: Biomedical | H36: Add on | I36: Equipment | J36: Approved | K36: 394000 | L36: Monarch Sales, Vadodara | M36: DLPC-3 | O36: =460000*3/100 -> 13800
A37: 13 | B37: 9 | C37: Laser and fiber optics Trainer Kit | D37: 1 | E37: 490000 | F37: 490000 | G37: Biomedical | H37: Add on | I37: Equipment | J37: Approved | K37: 484030 | L37: Mechmatics Engineering Pvt. Ltd, Ahmedabad | M37: DLPC-3
A38: 14 | B38: 11 | C38: 3D Printer | D38: 1 | E38: 120000 | F38: 120000 | G38: Biomedical | H38: Add on | I38: Equipment | J38: Approved | K38: 79920 | L38: Wol 3D India Limited, Mumbai | M38: DLPC-3
A39: 15 | B39: 0 | C39: EPABX System | D39: 1 | E39: 108000 | F39: 108000 | G39: Central Store-Equipment | H39: Add on | I39: Equipment | J39: Approved | K39: 108000 | L39: ASPIRETECHNO GLOBAL PRIVATE LIMITED | M39: DLPC-3
A40: 16 | B40: 79 | C40: Reynolds Apparatus | D40: 1 | E40: 60000 | F40: 60000 | G40: Rubber Tech | H40: U.G | I40: Equipment | J40: Approved | K40: 47700 | L40: EIE Instruments Pvt. Ltd | M40: DLPC-3
A41: 1 | B41: 8 | C41: Portable concrete core cutter | D41: 1 | E41: 360000 | F41: 360000 | G41: Applied Mechanics | H41: U.G | I41: Equipment | J41: Order placed | K41: 202000 | L41: Intellitest Solutions Pvt. Ltd., Faridabad | M41: DLPC-5
A42: =A41+1 -> 2 | B42: 15 | C42: SCISSOR LIFT | D42: 1 | E42: 200000 | F42: 200000 | G42: Automobile | H42: U.G | I42: Equipment | J42: Order placed | K42: 131000 | L42: Pantron Automation Pvt. Ltd. | M42: DLPC-5
A43: =A82+1 -> 20 | B43: 37 | C43: Probe Sonicator | D43: 1 | E43: 480000 | F43: 480000 | G43: Chemical | H43: U.G | I43: Equipment | J43: Order placed | K43: 121400 | L43: Ravi Scientific Industries | M43: DLPC-5
A44: =A43+1 -> 21 | B44: 86 | C44: PELTON WHEEL TURBINE TEST RIG | D44: 1 | E44: 490000 | F44: 490000 | G44: Mechanical | H44: U.G | I44: Equipment | J44: Order placed | K44: 169000 | L44: Ether Engineers, Ambala | M44: DLPC-5
A45: =A44+1 -> 22 | B45: 111 | C45: PCB prototyping machine | D45: 1 | E45: 500000 | F45: 500000 | G45: Electrical | H45: U.G | I45: Equipment | J45: Order placed | K45: 400000 | L45: Dinesh Scientific,Haryana | M45: DLPC-5
A46: =A45+1 -> 23 | B46: 112 | C46: Electrical machine trainer | D46: 2 | E46: 800000 | F46: 1600000 | G46: Electrical | H46: U.G | I46: Equipment | J46: Order placed | K46: 242787 | L46: Araby Technologies,Pune | M46: DLPC-5
A47: =A46+1 -> 24 | B47: 2 | C47: Digital Electronics Kits (With Additional Cards) | D47: 9 | E47: 55550 | F47: 499950 | G47: I.C | H47: Add on | I47: Equipment | J47: Not Approved | K47: 0 | L47: Kitek Technologies & All tech | M47: DLPC-5 | N47: 405000
...

Sheet All Summary
A1: LDCE-Purchase Expenditure-2025-26 as on 31/03/2026
G2: A | H2: B | I2: C | J2: D | K2: E | L2: F = B- C | M2: G | N2: H | O2: I
A3: Dept. (Equipment Demand) | B3: U.G | C3: P.G | D3: Total Demand @ New Item-Eq. | E3: Commited Budget to be spent | G3: Process | H3: Dept. Commitment @ meeting 05-02-26 | I3: Order Placed | J3: Under DLPC-Eqp. | K3: Under DPC-Eqp. | L3: Diff. Commitment minus Order placed | M3: Bid Cancelled | N3: Not Supply/ Rejected | O3: Bill Amount
A4: Applied Mechanics | B4: 2097000 | C4: 0 | D4: =B4+C4 -> 2097000 | E4: =600000+-600000+2000000 -> 2000000 | G4: =87000+80000+360000+1500000+30000 -> 2057000 | H4: 1550000 | I4: =17079+202000+1081920+167700 -> 1468699 | L4: =H4-I4 -> 81301 | N4: 371780 | O4: =9899+3000+1980+1080800 -> 1095679
A5: Automobile | B5: 884500 | C5: 0 | D5: =B5+C5 -> 884500 | E5: 550000 | G5: =515000+150000+100000 -> 765000 | H5: 350000 | I5: =16000+318600 -> 334600 | L5: =H5-I5 -> 15400 | O5: =15920+129690+187600 -> 333210
A6: Biomedical | B6: 1220000 | C6: 0 | D6: =B6+C6 -> 1220000 | E6: 3000000 | G6: 3000000 | H6: 1123500 | I6: =48300+58587+58410+394000+484030+79920 -> 1123247 | L6: =H6-I6 -> 253 | O6: =58410+58587+47576+79920+471929+384150 -> 1100572
A7: Chemical | B7: 1409000 | C7: 4700000 | D7: =B7+C7 -> 6109000 | E7: 12043837 | G7: =9159000+480000+3200000+150000+24900+24850+21900+24314+24900+72136+700000+1200000+2700000+25000+10000 -> 17817000 | H7: =5537000 -> 5537000 | I7: =21776+3020190+421500+121400+1890000+24900+24850+21900+24314+24900+63000+89000+498900+9996 -> 6256626 | K7: 3350000 | L7: =H7-I7 -> -719626 | N7: 498900 | O7: =21200+421500+564220+501970+576000+499000+121400+21890+24873+24192+89000+24601+24651+9896+848235+63000+1889000 -> 5724628 | P7: 89000-TED-11
A8: Civil | B8: 2399000 | C8: 0 | D8: =B8+C8 -> 2399000 | E8: 1200000 | G8: =535000+600000+2500000 -> 3635000 | H8: 1018000 | I8: 421500 | K8: 596250 | L8: =H8-I8 -> 596500 | O8: 421500
A9: Computer Engg. | B9: 1295000 | C9: 0 | D9: =B9+C9 -> 1295000 | E9: 0 | G9: 0 | H9: 0 | I9: 0 | L9: =H9-I9 -> 0 | O9: 0
A10: Electrical | B10: =2635000+4180000 -> 6815000 | C10: 0 | D10: =B10+C10 -> 6815000 | E10: 6600000 | G10: =4619000+1450000+18000+218000+1400000 -> 7705000 | H10: 5500000 | I10: =62800+353004+15930+201180+242787+400000+1453100 -> 2728801 | K10: =948000+1268000 -> 2216000 | L10: =H10-I10 -> 2771199 | M10: 401000 | N10: 970100 | O10: =24800+15000+7000+16000+90764+123668+130583-341+153209+20268+21971+17487+398000+483000+239144 -> 1740553
A11: EC | B11: 0 | C11: 0 | D11: 0 | E11: 3500000 | G11: 3500000 | H11: 5243000 | I11: 5242500 | L11: =H11-I11 -> 500 | N11: 5242500 | O11: 0
A12: Environment | B12: 2081000 | C12: 675000 | D12: =B12+C12 -> 2756000 | E12: 3051000 | G12: =2581000+350000+400000+150000+450000+250000 -> 4181000 | H12: 1588000 | I12: =5754+22001+421500+940585+197800 -> 1587640 | L12: =H12-I12 -> 360 | M12: 1780000 | O12: =5754+21891+421500+202280+68630+322775+41900+301950+134800+63000 -> 1584480
A13: IC | B13: 0 | C13: 0 | D13: =B13+C13 -> 0 | E13: 13812000 | G13: =5034950+8776861 -> 13811811 | H13: =691000+2807000 -> 3498000 | I13: =269000+421500+2807000+33000+16560+50500 -> 3597560 | L13: =H13-I13 -> -99560 | M13: 1119950 | N13: 1125560 | O13: =421500+269000+1695000+33000+50500 -> 2469000
A14: IT | B14: 150000 | C14: 0 | D14: =B14+C14 -> 150000 | E14: 0 | G14: 0 | H14: 0 | I14: 0 | L14: =H14-I14 -> 0 | M14: 0 | O14: 0
A15: Library | B15: 0 | C15: 0 | D15: =B15+C15 -> 0 | E15: 0 | G15: 0 | H15: 0 | I15: 0 | L15: =H15-I15 -> 0 | M15: 0 | O15: 0
A16: Mechanical | B16: 8130000 | C16: 1050000 | D16: =B16+C16 -> 9180000 | E16: =5000000-3200000 -> 1800000 | G16: =2080000+490000+26000+2000000+13440+13998+11478+490000+20000+1000000-900000+8000 -> 5252916 | H16: 1800000 | I16: =64400+22862+28785+11478+20000+169000+7680+236500 -> 560705 | K16: 1896000 | L16: =H16-I16 -> 1239295 | O16: =22862+28785+11306+19100+7680+63756+166465+236500 -> 556454 | P16: 236500-TED-11
A17: Plastic Tech | B17: 225000 | C17: 0 | D17: =B17+C17 -> 225000 | E17: 5500000 | G17: =360000+8000000 -> 8360000 | H17: 800000 | I17: =94400+145000 -> 239400 | L17: =H17-I17 -> 560600 | O17: 94900
A18: Rubber | B18: 1110000 | C18: 0 | D18: =B18+C18 -> 1110000 | E18: 8028000 | G18: =1495000+6533000 -> 8028000 | H18: 3200000 | I18: =189000+47700+289900+168800+95480+297505+280000 -> 1368385 | K18: =1330000+570000 -> 1900000 | L18: =H18-I18 -> 1831615 | N18: 289900 | O18: =189000+46746+168800+95480+297505+280000+145000 -> 1222531
A19: S & H | B19: 0 | C19: 0 | D19: 0 | E19: 2800000 | G19: =23225+2289500+310000+90000 -> 2712725 | H19: 2363000 | I19: =22224+1000+2339212 -> 2362436 | L19: =H19-I19 -> 564 | N19: 212224 | O19: =990+84010+17230+76500+296403+266992+474414+231766+274912+37328+26214+23973+339470 -> 2150202
A20: Textile | B20: 15222000 | C20: 415000 | D20: =B20+C20 -> 15637000 | E20: 6000000 | G20: =1436700+111000+25000+2450000+302000 -> 4324700 | H20: 3939000 | I20: =99200+864480+94636+15000-15275+2425009+455740 -> 3938790 | L20: =H20-I20 -> 210 | O20: =24875+9850+23760+23760+15000+94636+864480+257240+198500+1184220+1230700 -> 3927021
A21: Common Purchase (Central Store) | B21: 24985000 | C21: 3870000 | D21: =B21+C21 -> 28855000 | E21: =3350000+1000000+108000 -> 4458000 | G21: =3350000+1000000+28000+100000 -> 4478000 | H21: 4200000 | I21: =3068600+23084+79910 -> 3171594 | L21: =H21-I21 -> 1028406 | O21: =23084+3053257+78711 -> 3155052
A22: Institute Services
A23: Grand Total | B23: =SUM(B4:B21) -> 68022500 | C23: =SUM(C4:C21) -> 10710000 | D23: =B23+C23 -> 78732500 | E23: =SUM(E4:E21) -> 74342837 | G23: =SUM(G4:G21) -> 89628152 | H23: =SUM(H4:H22) -> 41709500 | I23: =SUM(I4:I22) -> 34402483 | J23: =SUM(J4:J22) -> 0 | K23: =SUM(K4:K22) -> 9958250 | L23: =SUM(L4:L22) -> 7307017 | M23: =SUM(M4:M21) -> 3300950 | N23: =SUM(N4:N21) -> 8710964 | O23: =SUM(O4:O21) -> 25575782 | P23: Total Expenditure as on 28-03-2026 till Sr.no.192 of bill reg. | R23: last Textile
A24: Admin approval limit | H24: 38673000 | J24: =I23+J23+K23 -> 44360733 | K24: Grand total of L1 | N24: Penalty | O24: =Sheet1!G51 -> 115737
A25: for Equipment | J25: =27261311+8000000+6533000+2000000+1400000+360000+100000-150000+2500000-490000-140000-2100000-360000-350000-3972950-500000+401000-400000-3105690-1577810-108000+888000-1037690-2655000-225000-2000000-100000-1250000-520000-135000-385000-350000+250000-650000-1400000 -> 25731171 | K25: Bid / Direct Purchase In process | Q25: =O23-236500-89000 -> 25250282
J26: =I23-O23-N23-O24 -> 0 | K26: Pending upcoming bills from Order Placed
G27: =G23-J25-J24-G28-M23 -> 0 | H27: Error | K27: Out of Total Expenditure | M27: TED-11-Eq. | O27: =89000+236500 -> 325500
G28: =8919219-1347+134000+1457213+158000+1291238+272457-401000+418080+358600+232000+1310000+298690+1037690+253900+130600+735000+72136+-896500+-7085-900+70000+201100-516560-17847+682000+320+24200+20094 -> 16235298 | H28: Price diff. L1 vs Processed | K28: Out of Total Expenditure | M28: TED-5-Eq. | O28: 25250282
I29: Exp. | J29: Admin Approval | K29: % utilization
H30: Equipment | I30: =O23 -> 25575782 | J30: 38673000 | K30: =I30*100/J30 -> 66.133432 | N30: New item Exp. | O30: =O23+I31+I32+I33 -> 36995029
H31: IT Equipment | I31: 290959 | J31: 34651000 | K31: =I31*100/J31 -> 0.83968428 | N31: Textile NTTM | O31: 18303951
H32: Books | I32: =161069 -> 161069 | J32: 1482000 | K32: =I32*100/J32 -> 10.868354 | N32: AMC for Services | O32: 25650568
H33: Furniture | I33: 10967219 | J33: 17962000 | K33: =I33*100/J33 -> 61.057894 | N33: Contingency | O33: 1157845
H34: Total New item Exp. | I34: =SUM(I30:I33) -> 36995029 | J34: =SUM(J30:J33) -> 92768000 | K34: =I34*100/J34 -> 39.879084 | M34: All Expenditure | O34: =SUM(O30:O33) -> 82107393
H36: Books-TED-5 apart from above summary | K36: Textile Engg- NTTM Fund apart from above summary | N36: ='Furniture-2025-26'!E16 -> 10967219 | O36: Furniture, TED-5
G37: 1 | H37: 20027 | J37: 1 | K37: 205000 | N37: 25650568 | O37: AMC for Services
G38: 2 | H38: 15771 | J38: 2 | K38: 60416 | N38: ='IT-Equipment'!I5 -> 290958.52 | O38: IT equipment
G39: 3 | H39: 21330 | J39: 3 | K39: 549880 | N39: ='Conti. Office Exp etc..'!D32 -> 1157845 | O39: Office Expense/ Contingency/ Consumable
G40: 4 | H40: 21141 | J40: 4 | K40: 3996700
G41: 5 | H41: 22180 | J41: 5 | K41: 6100000
...

Sheet Furniture-2025-26
A1: LDCE-New Item-2025-26-Furniture Purchased
A2: Sr.No. | B2: Description | C2: Qty. | D2: Estimated Amount | E2: Bill Amount
A3: 1 | B3: Seminar chair | C3: 200 | D3: 1100000 | E3: 598634
A4: 2 | B4: Computer Chair, Revolving Chair for Cl-1 & Cl-3 | C4: 350 | D4: 2030000 | E4: 832680
A5: 3 | B5: Class room Bench-3 Seater & 2-Seater | C5: =200+150 -> 350 | D5: 3900000 | E5: 2093000
A6: 4 | B6: Steel Cupboard Major, Minor, Laboratory Cupboard & Library Cupboard | C6: 190 | D6: 4206000 | E6: 1753425
A7: 5 | B7: Revolving Chair Class-2 & Executive Chair | C7: 120 | D7: 1970000 | E7: 996000
A8: 6 | B8: Steel filing Cabinet | C8: 40 | D8: 1024000 | E8: 417240
A9: 7 | B9: Visitor Chair | C9: 40 | D9: 500000 | E9: 188000
A10: 8 | B10: Computer table & Office table for Cl-1,2 & 3 | C10: 400 | D10: 7520000 | E10: 2887000
A11: 9 | B11: Class room table | C11: 40 | D11: 360000 | E11: 208880
A12: 10 | B12: Lab Stool , Wooden & Steel | C12: 400 | D12: 800000 | E12: 863100
A13: 11 | B13: Open Rack for Library | C13: 20 | D13: 140000 | E13: 129260
A14: 12 | B14: Compactor | C14: 3 | D14: 6000000 | E14: 0
A15: 13 | B15: Class Room Board & Notice Board | C15: 40 | D15: 700000 | E15: 0
D16: =SUM(D3:D15) -> 30250000 | E16: =SUM(E3:E15) -> 10967219

Sheet IT-Equipment
A1: Sr.No. | B1: Name of Item | C1: Qty | D1: Rate per unit | E1: Total Amount As per AT | F1: Penalty | G1: Bill to be paid to the party | H1: GIL service charge | I1: Grand total Bill paid | J1: Po Date | K1: Due date for Supply & Installation | L1: Installation Complition | M1: Party | N1: Bill.No. | O1: Bill. Date. | P1: Bill Amount
A2: 1 | B2: A4 Multifunction laser Printer | C2: 12 | D2: 10330 | E2: =C2*D2 -> 123960 | F2: 0 | G2: =E2-F2 -> 123960 | H2: =G2*3/100 -> 3718.8 | I2: =G2+H2 -> 127678.8 | J2: 45895 | K2: As per AT | L2: intime | M2: Printmark Technologies Pvt. Ltd. | N2: PMT/GJ25-26/0052 | O2: 45904 | P2: 123960
A3: 2 | B3: A4 Mmono Inkjet Printer | C3: 12 | D3: 10847 | E3: =C3*D3 -> 130164 | F3: 0 | G3: =E3-F3 -> 130164 | H3: =G3*3/100 -> 3904.92 | I3: =G3+H3 -> 134068.92 | J3: 45895 | K3: As per AT | L3: intime | M3: Earth Syscom Pvt. Ltd. | N3: SI/ES/SEP25/0098 | O3: 45919 | P3: 130164
A4: 3 | B4: A4 duuplex Scanner | C4: 2 | D4: 14180 | E4: =C4*D4 -> 28360 | F4: 0 | G4: =E4-F4 -> 28360 | H4: =G4*3/100 -> 850.8 | I4: =G4+H4 -> 29210.8 | J4: 45895 | K4: As per AT | L4: intime | M4: Earth Syscom Pvt. Ltd. | N4: SI/ES/OCT25/0035 | O4: 45938 | P4: 28360
G5: =SUM(G2:G4) -> 282484 | H5: =SUM(H2:H4) -> 8474.52 | I5: =SUM(I2:I4) -> 290958.52 | M5: GIL Service Charge for 12 Nos. Print mark Printers | N5: Sep=2526-H-42 | O5: 45923 | P5: 3718.8
M6: GIL Service Charge for 12 Nos. Canon Printers | N6: Oct-2526-H-2 | O6: 45933 | P6: 3905
M7: GIL Service Charge for 12 Nos. Canon Printers | N7: Oct-2526-H-76 | O7: 45958 | P7: 851
A9: Under Process
A10: Sr.No. | B10: Name of Item | C10: Qty | D10: Rate per unit | E10: Estimated Cost
A11: 1 | B11: Projector sets | C11: 48 | D11: =E11/C11 -> 75000 | E11: 3600000

Sheet Grant
A1: F.Y-2025-26-L.D COLLEGE OF ENGINEERING, AHMEDABAD , NEW ITEMS GRANT DETAILS
A2: Rs. In Lakh | D2: NI-Equipment | G2: NI-Furniture | J2: NI-Books | M2: NI-Maintenance | P2: Total (Except IT HW & SW) | S2: IT-HW & SW | V2: Grand total
A3: Budget Head---------> | D3: TED-5 | E3: TED-11 | G3: TED-5 | H3: TED-11 | J3: TED-5 | K3: TED-11 | M3: TED-5 | N3: TED-11 | P3: TED-5 | Q3: TED-11 | S3: TED-5 | T3: TED-11 | V3: TED-5 | W3: TED-11
A4: Administrative approval Rs. In Lakh | D4: 334.12 | E4: 52.61 | G4: 161.01 | H4: 18.61 | J4: 10.71 | K4: 4.11 | M4: 13.39 | N4: 1.72 | P4: =D4+G4+J4+M4 -> 519.23 | Q4: =E4+H4+K4+N4 -> 77.05 | S4: 346.51 | T4: 0 | V4: =P4+S4 -> 865.74 | W4: =Q4+T4 -> 77.05
A5: Total (TED-5+TED-11) | D5: =D4+E4 -> 386.73 | G5: =G4+H4 -> 179.62 | J5: =J4+K4 -> 14.82 | M5: =M4+N4 -> 15.11 | P5: =P4+Q4 -> 596.28 | S5: =S4+T4 -> 346.51 | V5: =V4+W4 -> 942.79
A7: Grant allocated-21/05/2025 | D7: =D4/4 -> 83.53 | E7: =E4/4 -> 13.1525 | F7: =F4/4 -> 0 | G7: =G4/4 -> 40.2525 | H7: =H4/4 -> 4.6525 | I7: =I4/4 -> 0 | J7: =J4/4 -> 2.6775 | K7: =K4/4 -> 1.0275 | ... Q7: =Q4/4 -> 19.2625 | S7: 0 | T7: 0 | V7: =P7+S7 -> 129.8075 | W7: =Q7+T7 -> 19.2625
A8: Grant allocated-01/07/2025 | D8: =D4/4 -> 83.53 | E8: =E4/4 -> 13.1525 | F8: =F4/4 -> 0 | G8: =G4/4 -> 40.2525 | H8: =H4/4 -> 4.6525 | I8: =I4/4 -> 0 | J8: =J4/4 -> 2.6775 | K8: =K4/4 -> 1.0275 | ... R8: =R4/4 -> 0 | S8: 0 | T8: =T4/4 -> 0 | U8: =U4/4 -> 0 | V8: =P8+S8 -> 129.8075 | W8: =Q8+T8 -> 19.2625
A9: Grant allocated-16/10/2025 | D9: 0 | E9: 0 | G9: 0 | H9: 0 | J9: 0 | K9: 0 | M9: 0 | N9: 0 | P9: 0 | Q9: 0 | S9: 2.62 | T9: 0 | V9: =P9+S9 -> 2.62 | W9: 0
A12: Total Grant Allocated | D12: =SUM(D7:D11) -> 167.06 | E12: =SUM(E7:E11) -> 26.305 | F12: =SUM(F7+F8) -> 0 | G12: =SUM(G7:G11) -> 80.505 | H12: =SUM(H7:H11) -> 9.305 | I12: =SUM(I7+I8) -> 0 | J12: =SUM(J7:J11) -> 5.355 | K12: =SUM(K7:K11) -> 2.055 | L12: =SUM(L7+L8) -> 0 | M12: =SUM(M7:M11) -> 6.695 | N12: =SUM(N7:N11) -> 0.86 | O12: =SUM(O7+O8) -> 0 | P12: =SUM(P7:P11) -> 259.615 | Q12: =SUM(Q7:Q11) -> 38.525 | R12: =SUM(R7+R8) -> 0 | S12: =SUM(S7:S11) -> 2.62 | T12: =SUM(T7:T11) -> 0 | U12: =SUM(U7+U8) -> 0 | V12: =SUM(V7:V11) -> 262.235 | W12: =SUM(W7:W11) -> 38.525
A13: Total (TED-5+TED-11) | D13: =D12+E12 -> 193.365 | G13: =G12+H12 -> 89.81 | J13: =J12+K12 -> 7.41 | M13: =M12+N12 -> 7.555 | P13: =P12+Q12 -> 298.14 | S13: =S12+T12 -> 2.62 | V13: =V12+W12 -> 300.76
P14: =#REF!-#REF!-#REF! -> #REF!
A16: Summary of Expenditure: | D16: Rs. In lakh | E16: Budget head
A17: Equipment
A18: Books
A19: Furniture
A20: Conti. /Consumable/Office expenses
A21: IT equipment
A22: Ansys software renewal under DEDF
A23: Total | D23: =SUM(D17:D22) -> 0
A25: Not Executed Orders | D25: Rs. In lakh
A26: Disqualified in DLPC
A27: Not Supplied/Not Executed
A28: Books Expenditure
A29: Total DPC Not approved (Eq & Fur) & Manpower out sourcing/ Housekeeping for Hostel
A30: Total | D30: =SUM(D26:D29) -> 0
B33: 48914232 | D33: =B33/100000 -> 489.14232

Sheet DPC Files after Diwali
A1: L D College of Engineering, Ahmedabad
A2: Files submitted to DTE for DPC
A3: Sr No | B3: Particulars | C3: Department | D3: E-Sarkar No | E3: Date of Submission | F3: L1 Value
A4: 1 | B4: Shifting of Four Departments to New Buidling | C4: Central Store | D4: 5894/e-tappal/01/2026 | E4: 46023 | F4: 1320000
A5: 2 | B5: Compression Testing Machine | C5: Applied Mechanics | D5: 2955/e-tappal/01/2026 | E5: 46023 | F5: 1081920
A6: 3 | B6: Furniture Computer Table & Office Table For Class - 1,2,3 | C6: Central Store | D6: 224250/e-tappal/12/2025 | E6: 46006 | F6: 2888000
A7: 4 | B7: Furniture Classroom Desking 2 & 3 Seater | C7: Central Store | D7: 181931/e-tappal/12/2025 | E7: 46003 | F7: 2094000
A8: 5 | B8: Electronics Workbench | C8: EC, IC, BM | D8: 277353/e-tappal/10/2025 | E8: 45948 | F8: 5242500
A9: 6 | B9: Transducer & Measurment Trainer Kits | C9: IC | D9: 72186/e-tappal/01/2026 | E9: 46027 | F9: 1109000
A10: 7 | B10: Advance Microcontroller Trainer Kits | C10: IC | D10: 72276/e-tappal/01/2026 | E10: 46027 | F10: 1698000
A11: 8 | B11: High Pressure Continuous Flow Reactor | C11: Chemical | D11: 102836/e-tappal/01/2026 | E11: 46029 | F11: 1890000
A12: 9 | B12: Microprocessor & Micro Controller Trainer Kits | C12: IC | F12: 530000
A13: 10 | B13: Process Control Trainer, Pressure, Temp. , Flow | C13: IC | F13: 783000
A14: 11 | B14: 4 Axis Articulated Robot Arm ( MATLAB Compitable) | C14: IC | F14: 999000
A15: 12 | B15: Process Control Trainer, Flow , Level with Pneumatic Control Valve | C15: IC | F15: 764000
A16: 13 | B16: Basic Electronics & Measurement Kits | C16: IC | F16: 637410
E17: Total | F17: =SUM(F4:F11) -> 17323420
A18: Files Under NTTM Fund
A19: 1 | B19: Thermogravymetric analyzer | C19: Textile | D19: 264462/e-tappal/11/2025 | E19: 45979 | F19: 4985010
A20: 2 | B20: FTIR | C20: Textile | D20: 30996/e-tappal/11/2025 | E20: 45982 | F20: 6120000
A21: 3 | B21: Thermal conductivity tester | C21: Textile | D21: 139151/e-tappal/11/2025 | E21: 45972 | F21: 3997700
A22: 4 | B22: Porometer | C22: Textile | D22: 139152/e-tappal/11/2025 | E22: 45972 | F22: 7000000
A23: 5 | B23: 16 layer orthogonal weaving loom | C23: Textile | D23: 139697/e-tappal/11/2025 | E23: 45972 | F23: 6800000
A24: 6 | B24: Differential scanning calorimeter | C24: Textile | D24: 139562/e-tappal/11/2025 | E24: 45972 | F24: 4985000
A25: 7 | B25: Microscope | C25: Textile | D25: 139486/e-tappal/11/2025 | E25: 45972 | F25: 1985000
E26: Total | F26: =SUM(F19:F25) -> 35872710
A27: Grnad Total | F27: =F17+F26 -> 53196130

Sheet Sheet2
A1: Sr.No. | B1: Name of Equipment | C1: Party | D1: Bill.No. | E1: Bill. Date. | F1: Bill Amount | G1: Qty. | H1: Amount Paid from A/c | I1: Transaction details | J1: Transaction Date.
A2: 1 | B2: A4 Multifunction laser Printer | C2: Printmark Technologies Pvt. Ltd. | D2: PMT/GJ25-26/0052 | E2: 45904 | F2: 123960 | G2: 12
A3: 2 | B3: A4 Mmono Inkjet Printer | C3: Earth Syscom Pvt. Ltd. | D3: SI/ES/SEP25/0098 | E3: 45919 | F3: 130164 | G3: 12
A4: 3 | B4: A4 duuplex Scanner | C4: Earth Syscom Pvt. Ltd. | D4: SI/ES/OCT25/0035 | E4: 45938 | F4: 28360 | G4: 2
A5: 4 | B5: GIL Service Charge for 12 Nos. Print mark Printers | C5: GIL, Gandhinagar | D5: Sep=2526-H-42 | E5: 45923 | F5: 3718.8 | G5: 12
A6: 5 | B6: GIL Service Charge for 12 Nos. Canon Printers | C6: GIL, Gandhinagar | D6: Oct-2526-H-2 | E6: 45933 | F6: 3905 | G6: 12
A7: 6 | B7: GIL Service Charge for 02 Nos. Canon Scanner | C7: GIL, Gandhinagar | D7: Oct-2526-H-76 | E7: 45958 | F7: 851 | G7: 2
A8: 7 | B8: A4 Multifunction laser Printer- Gymkhana Fund | C8: Printmark Technologies Pvt. Ltd. | D8: PMT/GJ25-26/0101 | E8: 45924 | F8: 51650 | G8: 5
A9: 8 | B9: GIL Service Charge for 12 Nos. Print mark Printers- Gymkhana fund | C9: GIL, Gandhinagar | D9: Oct-2526-H-1 | E9: 45933 | F9: 1549.03 | G9: 5
A21: DPC order released
B22: Name of Equipment | C22: L1 Amount | D22: Party | E22: Dept. | H22: Electronics Workbench | I22: 5242500 | J22: Premier Enterprise | K22: EC,IC,Biomedical | L22: Under DPC
B23: Air Conditioners-67 Nos. | C23: 3068600 | D23: Vedanta Equipment Pvt. Ltd. | E23: Central Store | H23: Compression Testing M/C | I23: 1081920 | J23: EIE Instruments | K23: Applied Mechanics | L23: Under DPC
B24: Miniature Rotor Spinning M/c | C24: 1189220 | D24: T4 Textultants Pvt. Ltd. | E24: Textile | H24: Shifting Work | I24: 1320000 | J24: Vikash Excellent Roadlines | K24: Central Store | L24: Under DPC
B25: Miniature Ring frame | C25: 1235789 | D25: T4 Textultants Pvt. Ltd. | E25: Testile
B26: Sound Level Meter | C26: 1686000 | D26: Technovision Analytical | E26: IC, Civil. Chemical, Environment
B27: Total | C27: =SUM(C23:C26) -> 7179609
A29: Order released for services
B30: Name of Service | C30: L1 Amount
B31: 1. Fire Safety for Hostel | C31: 2345000
B32: 2 AMC-Hostel- RO | C32: 164880
B33: 3. AMC-Institute-HK | C33: 9908765 | K33: 3600000 | L33: Projector sets -proposal under process at GIL-Qty.48 Sets
B34: 4 AMC-Hostel HK | C34: 4565977
B35: 5. AMC for RO & WC-Institute | C35: 235950
B36: 6. Manpower Outsourcing | C36: 6479737 | K36: 30250000 | L36: Furniture bids under process-13 items
B37: 7. AMC CWAN | C37: 199999
B38: 8. AMC Air conditioner | C38: 430260
B39: 9. AMC for Shifting Work (Handling & Transport Service) | C39: 1320000
B40: Total | C40: =SUM(C31:C39) -> 25650568
A42: Order released against Contingency
C43: L1 Amount
B44: 1. Tube light _Electrical | C44: 81000 | D44: Contingency
B45: 2. EPABX System for office | C45: 108000 | D45: Office Expences
B46: Total | C46: =SUM(C44:C45) -> 189000

Sheet DPC Files after Diwali (2)
A1: L D College of Engineering, Ahmedabad
A2: Files submitted to DTE for DPC
A3: Sr No | B3: Particulars | C3: Department | D3: E-Sarkar No | E3: Date of Submission | F3: L1 Value
A4: 1 | B4: Shifting of Four Departments to New Buidling | C4: Central Store | D4: 5894/e-tappal/01/2026 | E4: 46023 | F4: 1320000
A5: 2 | B5: Compression Testing Machine | C5: Applied Mechanics | D5: 2955/e-tappal/01/2026 | E5: 46023 | F5: 1081920
A6: 5 | B6: Electronics Workbench | C6: EC, IC, BM | D6: 277353/e-tappal/10/2025 | E6: 45948 | F6: 5242500
A7: 6 | B7: Transducer & Measurment Trainer Kits | C7: IC | D7: 72186/e-tappal/01/2026 | E7: 46027 | F7: 1109000
A8: 7 | B8: Advance Microcontroller Trainer Kits | C8: IC | D8: 72276/e-tappal/01/2026 | E8: 46027 | F8: 1698000
A9: 8 | B9: High Pressure Continuous Flow Reactor | C9: Chemical | D9: 102836/e-tappal/01/2026 | E9: 46029 | F9: 1890000
A10: 9 | B10: Microprocessor & Micro Controller Trainer Kits | C10: IC | F10: 530000
A11: 10 | B11: Process Control Trainer, Pressure, Temp. , Flow | C11: IC | F11: 783000
A12: 11 | B12: 4 Axis Articulated Robot Arm ( MATLAB Compitable) | C12: IC | F12: 999000
A13: 12 | B13: Process Control Trainer, Flow , Level with Pneumatic Control Valve | C13: IC | F13: 764000
A14: 13 | B14: Basic Electronics & Measurement Kits | C14: IC | F14: 637410
E15: Total | F15: =SUM(F4:F9) -> 12341420
A16: Files Under NTTM Fund
A17: 1 | B17: Thermogravymetric analyzer | C17: Textile | D17: 264462/e-tappal/11/2025 | E17: 45979 | F17: 4985010
A18: 2 | B18: FTIR | C18: Textile | D18: 30996/e-tappal/11/2025 | E18: 45982 | F18: 6120000
A19: 3 | B19: Thermal conductivity tester | C19: Textile | D19: 139151/e-tappal/11/2025 | E19: 45972 | F19: 3997700
A20: 4 | B20: Porometer | C20: Textile | D20: 139152/e-tappal/11/2025 | E20: 45972 | F20: 7000000
A21: 5 | B21: 16 layer orthogonal weaving loom | C21: Textile | D21: 139697/e-tappal/11/2025 | E21: 45972 | F21: 6800000
A22: 6 | B22: Differential scanning calorimeter | C22: Textile | D22: 139562/e-tappal/11/2025 | E22: 45972 | F22: 4985000
A23: 7 | B23: Microscope | C23: Textile | D23: 139486/e-tappal/11/2025 | E23: 45972 | F23: 1985000
E24: Total | F24: =SUM(F17:F23) -> 35872710
A25: Grnad Total | F25: =F15+F24 -> 48214130

Sheet DPC-February-2026
A1: Sr.No. | B1: Name of item | C1: Qty. | D1: Unit Estimated Cost | E1: Total Estimated Cost | F1: L1 Price | G1: L1 Party | H1: Category of Item | I1: e-file No. | J1: Date | K1: Dept.
A2: 1 | B2: Augmented Reality Welding Simulator | C2: 1 | D2: 2000000 | E2: =C2*D2 -> 2000000 | F2: 1896000 | G2: Simbott Technologies | H2: Equipment | I2: 104271/e-tappal/02/2026 | J2: 46060 | K2: Mechanical
A3: 3 | B3: U-V Visible Sp[ectro photo meter | C3: 1 | D3: 600000 | E3: =C3*D3 -> 600000 | F3: 596250 | G3: Labtronik | H3: Equipment | I3: 216565/e-tappal/02/2026 | J3: 46069 | K3: Civil
A4: 2 | B4: Mobile Storage Compactor | C4: 3 | D4: 2000000 | E4: =C4*D4 -> 6000000 | F4: 953016 | G4: Veer Industries , Surat | H4: Furniture | I4: 207678/e-tappal/02/2026 | J4: 46069 | K4: Central Store
A5: 4 | B5: Dry earase writing board & Pinup Notice board | C5: =40+40 -> 80 | D5: - | E5: 915000 | F5: 652000 | G5: Prince board India , Mumbai | H5: Furniture | I5: 237033/e-tappal/02/2026 | J5: 46070 | K5: Central Store
A6: 5 | B6: Canteen Services | C6: - | D6: - | E6: - | F6: 72000 | G6: Jyoti Hospitality Services | H6: Canteen Forward Auction | I6: 282002/e-tappal/02/2026 | J6: 46072 | K6: Applied Mechanics
A7: 6 | B7: Moving Die Rheometer (MDR) | C7: 1 | D7: 520000 | E7: =C7*D7 -> 520000 | F7: 570000 | G7: Stech Engineers, Maharashtra | H7: Equipment | K7: Rubber Technology
A8: 9 | B8: UV- Accelerated Weathering Tester-Digital | C8: 1 | D8: 1250000 | E8: =C8*D8 -> 1250000 | F8: 1330000 | G8: Stech Engineers, Maharashtra | H8: Equipment | K8: Rubber Technology

Sheet Conti. Office Exp etc..
A1: Sr.No. | B1: Name of item | C1: Qty. | D1: Total Exp.
A2: 1 | B2: Sharp Tonner Cartridge | C2: 4 | D2: 23760
A3: 2 | B3: Box files | C3: 350 | D3: 23828
A4: 3 | B4: Spring Files | C4: 576 | D4: 23194
A5: 4 | B5: Filter Paper KP-1 | C5: 1 | D5: 1500
A6: 5 | B6: Cl-4 Employees Uniform Cl-4-07 Male +01 Female | C6: 8 | D6: 6095
A7: 6 | B7: PH Paper Strip | C7: 5 | D7: 1070
A8: 16 | B8: Dept. Mission Vision Plate | C8: 37 | D8: 24568
A9: 17 | B9: Emergency No. Exit plan Equipment Name & Misc Washroom M/F etc…plates. | C9: 147 | D9: 24255
A10: 18 | B10: Institute Mission Vision -S.S | C10: 4 | D10: 24800
A11: 19 | B11: Institute Mission Vision -S.S Foam Glossy tress | C11: 16 | D11: 24480
A12: 20 | B12: Dept. Mission Vision-Acrylic Plates | C12: 16 | D12: 24480
A13: 21 | B13: Sand which Panel Name plates-Acrylic Rect Sign Board | C13: 8 | D13: 22400
... A18: 34 | B18: Class-4 Employees Shooes -Chappal Bills-04 | C18: 4 | D18: 3200
A19: 37 | B19: Door mat Medium Size & Big Size | C19: =25+25 -> 50 | D19: 19750
A20: 38 | B20: Medical First Aid Kit Box | C20: 22 | D20: 21998
A21: 39 | B21: Medical First Aid Kit | C21: 22 | D21: 21890
A22: 52 | B22: Cl-4 Employees Uniform stiching bills Cl-4-06 Male +01 Female | C22: 7 | D22: 7550
A23: 53 | B23: LED Tube light | C23: 1000 | D23: 81000
A24: 61 | B24: Scale , Calculator | C24: =100+40 -> 140 | D24: 9412
A25: 62 | B25: Gases Refilling in Chemical dept. | C25: 4 | D25: 6962
A26: 89 | B26: EPABX System in Admin section | C26: 1 | D26: 108000
A27: 100 | B27: Stationary items | C27: - | D27: 54655
A28: 115 | B28: Ball pen for Cl-1 & Cl-2 Employees | C28: 256 | D28: 17408
A29: 116 | B29: Ball pen for Cl-3 Employees & Refill for Cl-1,2,3 Ball pen | C29: =29+1183 -> 1212 | D29: 16768
A30: 117 | B30: Activity based educational kits for Chemistry | C30: 1 | D30: 423720
A31: 129 | B31: Stationary Items | C31: - | D31: 69800
B32: Contingency/Office Expenses etc… | C32: Total | D32: =SUM(D2:D31) -> 1157845

Sheet Statement 2 (IT Equipment)-U.G
A1: Statement- 2
A2: Commissionerate of Technical Education, Gujarat State, Gandhinagar
A3: List of New Item for the Year 2025-26
A4: ( Consolidated list of IT Equipments for all Departments in this Single Sheet Only )
A5: Name of Inst. :- L.D College of Engineering,Ahmedabad Type of Course: (Diploma/UG/PG) | F5: Type of Course: U.G
H6: Amount in Rs. | I6: =F24 -> 73110000
A7: Sr. | B7: Name of Item | C7: Type of Item (Hardware/Software) | D7: Qty. Required | E7: Approx. Rate (Rs.) | F7: Total Amount (Rs.) | G7: Department / Discipline | H7: Avalable Qty. | I7: Detailed Justification
A8: 1 | B8: 2 | C8: 3 | D8: 4 | E8: 5 | F8: 6 | G8: 7 | H8: 8 | I8: 10
A9: 1 | B9: Desk top Computer | C9: Hardware | D9: 400 | E9: 65000 | F9: =D9*E9 -> 26000000 | G9: Various dept. | H9: 555 | I9: Required for multiple department
A10: 2 | B10: Desktop computer-High end | C10: Hardware | D10: 200 | E10: 78000 | F10: =D10*E10 -> 15600000 | G10: Various dept. | H10: 0 | I10: Required for multiple department
A11: 3 | B11: Laptop | C11: Hardware | D11: 94 | E11: 60000 | F11: =D11*E11 -> 5640000 | G11: Various dept. | H11: 35 | I11: Required for multiple department
A12: 4 | B12: Laptop-High end | C12: Hardware | D12: 30 | E12: 94000 | F12: =D12*E12 -> 2820000 | G12: Various dept. | H12: 0 | I12: Required for multiple department
A13: 5 | B13: Server | C13: Hardware | D13: 10 | E13: 275000 | F13: =D13*E13 -> 2750000 | G13: Various dept. | H13: 2 | I13: Required for multiple department
A14: 6 | B14: Mono laser printer | C14: Hardware | D14: 60 | E14: 15000 | F14: =D14*E14 -> 900000 | G14: Various dept. | H14: 17 | I14: Required for multiple department
A15: 7 | B15: Multi function printer | C15: Hardware | D15: 40 | E15: 25000 | F15: =D15*E15 -> 1000000 | G15: Various dept. | H15: 47 | I15: Required for multiple department
A16: 8 | B16: Projector | C16: Hardware | D16: 20 | E16: 62000 | F16: =D16*E16 -> 1240000 | G16: Various dept. | H16: 33 | I16: Required for multiple department
A17: 9 | B17: Network switch-24 port | C17: Hardware | D17: 30 | E17: 25000 | F17: =D17*E17 -> 750000 | G17: Various dept. | H17: 4 | I17: Required for multiple department
A18: 10 | B18: Network switch-8port | C18: Hardware | D18: 20 | E18: 20000 | F18: =D18*E18 -> 400000 | G18: Various dept. | H18: 0 | I18: Required for multiple department
A19: 11 | B19: WIFI Access Point | C19: Hardware | D19: 50 | E19: 2000 | F19: =D19*E19 -> 100000 | G19: Various dept. | H19: 7 | I19: Required for multiple department
A20: 12 | B20: Copier machine-Color | C20: Hardware | D20: 16 | E20: 200000 | F20: =D20*E20 -> 3200000 | G20: Various dept. | H20: 0 | I20: Required for multiple department
... A23: 15 | B23: Touch display-76" | C23: Hardware | D23: 16 | E23: 200000 | F23: =D23*E23 -> 3200000 | G23: Various dept. | H23: 2 | I23: Required for multiple dept.
A24: TOTAL | D24: =SUM(D9:D23) -> 1031 | F24: =SUM(F9:F23) -> 73110000 | H24: =SUM(H9:H23) -> 713
A25: નોંધ:-Diploma, UG અને PG અભ્યાસક્રમ માટે અલગ અલગ પત્રકો તૈયાર કરી માહિતી આપવી.
A26: ખાસ નોંધ:- પુરતા જસ્ટીફીકેશન વિના દરખાસ્ત સ્વીકારવામાં આવશે નહી.
A27: પ્રમાણપત્ર
A28: આથી પ્રમાણિત કરવામાં આવે છે કે, ઉક્ત ક્રમ નં. 01 થી 15 ઉપર દર્શાવેલ તમામ સાધનો/ઉપકરણો શૈક્ષણિક હેતુ તેમજ સંસ્થાનાં વહીવટ માટે ખુબજ આવશ્યક અને ઉપયોગી છે. આ ઉપરાંત હાલમાં સંસ્થા ખાતે વિવિધ વિદ્યાશાખાઓમાં ઉપલબ્ધ સાધનો/ઉપકરણોનાં જથ્થાની ચકાસણી કરવામાં આવેલ છે અને ત્યારબાદ ઉક્ત નવા સાધનો/ઉપકરણોની જરૂરીયાત હોઈ સને ૨૦૨૫-૨૬નાં વર્ષની નવી બાબત હેઠળ ખરીદી માટે ભલામણ કરવામાં આવે છે.
E30: Institute Seal | H30: Principal Sign

Sheet Statement 3 (Furniture)-U.G
A1: Statement - 3
A2: Commissionerate of Technical Education, Gujarat State, Gandhinagar
A3: List of New Item for the Year 2025-26
A4: ( Consolidated list of Furniture for all Departments in this Single Sheet Only )
A5: Name of Inst. :-L.D College of Engineering,Ahmedabad Type of Course: (Diploma/UG/PG) | F5: Type of Course: U.G
G6: Amount in Rs. | H6: =E24+E45 -> 32780000
A7: Sr. No. | B7: Name of Item | C7: Qty. Required | D7: Approx. Rate (Rs.) | E7: Total Amount (Rs.) | F7: Department / Discipline | G7: Avalable Qty. | H7: Detailed Justification
A8: 1 | B8: 2 | C8: 3 | D8: 4 | E8: 5 | F8: 6 | G8: 7 | H8: 8
A9: Furniture Costing Less than Rs.5.00 Lakh
A10: 1 | B10: Key Wall Mount Stand | C10: 28 | D10: 1000 | E10: =C10*D10 -> 28000 | F10: Various dept. | G10: 0 | H10: Required for multiple department
A11: 2 | B11: Library Magazine Stand | C11: 17 | D11: 3000 | E11: =C11*D11 -> 51000 | F11: Various dept. | G11: 0 | H11: Required for multiple department
A12: 3 | B12: Shoe Rack | C12: 31 | D12: 2000 | E12: =C12*D12 -> 62000 | F12: Various dept. | G12: 0 | H12: Required for multiple department
A13: 4 | B13: Notice board | C13: 34 | D13: 2000 | E13: =C13*D13 -> 68000 | F13: Various dept. | G13: 26 | H13: Required for multiple department
A14: 6 | B14: White Board | C14: 23 | D14: 5000 | E14: =C14*D14 -> 115000 | F14: Various dept. | G14: 10 | H14: Required for multiple department
A15: 7 | B15: Writing board-Green | C15: 17 | D15: 8000 | E15: =C15*D15 -> 136000 | F15: Various dept. | G15: 18 | H15: Required for multiple department
A16: 8 | B16: Writing Board-Black | C16: 17 | D16: 8000 | E16: =C16*D16 -> 136000 | F16: Various dept. | G16: 22 | H16: Required for multiple department
A17: 9 | B17: Soft Board (Pin Board) | C17: 79 | D17: 2000 | E17: =C17*D17 -> 158000 | F17: Various dept. | G17: 10 | H17: Required for multiple department
A18: 10 | B18: Visitors Chair | C18: 33 | D18: 5000 | E18: =C18*D18 -> 165000 | F18: Various dept. | G18: 24 | H18: Required for multiple department
A19: 11 | B19: Office table-Class-3 | C19: 32 | D19: 8000 | E19: =C19*D19 -> 256000 | F19: Various dept. | G19: 19 | H19: Required for multiple department
A20: =A19+1 -> 12 | B20: Office chair-Class-3 | C20: 40 | D20: 6000 | E20: =C20*D20 -> 240000 | F20: Various dept. | G20: 18 | H20: Required for multiple department
